<?xml version="1.0"?>
<robot name="board_skeleton1">
    <link name="world" />
		
		
    <link name="board_link">
        <inertial>
            <mass value="10.0" />
            <origin xyz="0 0 0" rpy="0 0 0" />
            <inertia ixx="1" ixy="0" ixz="0" iyy="1" iyz="0" izz="1" />
        </inertial> 
 
        <visual>
            <origin xyz="0 0 0" rpy="0 0 0" />
            <geometry>
                <box size="3.0 3.0 0.01" />
            </geometry>
			<material 
			name="">
			<color
			  rgba="0.7 0.9 0.7 1" />
		  </material>
        </visual>
        
        <collision group="default">
            <origisn xyz="0 0. 0" rpy="0 0 0" />
            <geometry>
                <box size="3.0 3.0 0.01" />
            </geometry>
        </collision>
    </link>
	

    <joint name="board_joint" type="floating">
        <origin xyz="9.5 -2.5 0.33" rpy="0 0 0.3" />
        <parent link="world" />
        <child link="board_link" />
    </joint>

	
    

	
</robot>
