<?xml version="1.0"?>
<robot name="box_skeleton2">
    <link name="world" />
	
    <link name="box2_link">
        <inertial>
            <mass value="1.0" />
            <origin xyz="0 0 0" rpy="0 0 0" />
            <inertia ixx="1" ixy="0" ixz="0" iyy="1" iyz="0" izz="1" />
        </inertial> 
 
        <visual>
            <origin xyz="0 0 0" rpy="0 0 0" />
            <geometry>
                <box size="0.7 0.7 1.2" />
            </geometry>
			<material 
			name="">
			<color
			  rgba="0.7 0 0.6 1" />
		  </material>
        </visual>
        
        <collision group="default">
            <origisn xyz="0 0 0" rpy="0 0 0" />
            <geometry>
                <box size="0.7 0.7 1.2" />
            </geometry>
        </collision>
    </link>
	

    <joint name="box2_joint_transform" type="floating">
        <origin xyz="4 1.5 0.6" rpy="0 0 0.2" />
        <parent link="world" />
        <child link="box2_link" />
    </joint>

	
    

	
</robot>
