<?xml version="1.0"?>
<robot name="box_skeleton4">
    <link name="world" />
	
    <link name="box4_link">
        <inertial>
            <mass value="1.0" />
            <origin xyz="0 0 0" rpy="0 0 0" />
            <inertia ixx="1" ixy="0" ixz="0" iyy="1" iyz="0" izz="1" />
        </inertial> 
 
        <visual>
            <origin xyz="0 0 0" rpy="0 0 0" />
            <geometry>
                <box size="1.0 0.5 0.4" />
            </geometry>
			<material 
			name="">
			<color
			  rgba="0.9 0.3 0 1" />
		  </material>
        </visual>
        
        <collision group="default">
            <origisn xyz="0 0 0" rpy="0 0 0" />
            <geometry>
                <box size="1.0 0.5 0.4" />
            </geometry>
        </collision>
    </link>
	

    <joint name="box4_joint_transform" type="floating">
        <origin xyz="10.9 -8 0.4" rpy="0 0 -0.4" />
        <parent link="world" />
        <child link="box4_link" />
    </joint>

	
    

	
</robot>
