<?xml version="1.0"?>
<robot name="windmill_skeleton3">
    <link name="world" />
	
    <link name="center_ball3_link">
        <inertial>
            <mass value="1.0" />
            <origin xyz="0 0 0" rpy="0 0 0" />
            <inertia ixx="1" ixy="0" ixz="0" iyy="1" iyz="0" izz="1" />
        </inertial> 
 
        <visual>
            <origin xyz="0 0 0" rpy="0 0 0" />
            <geometry>
                <sphere radius="0.1" />
            </geometry>
			<material 
			name="">
			<color
			  rgba="0 0 1 0.5" />
		  </material>
        </visual>
        
        <collision group="default">
            <origisn xyz="0 0 0" rpy="0 0 0" />
            <geometry>
                <sphere radius="0.1" />
            </geometry>
        </collision>
    </link>
	

    <joint name="center_ball3_joint" type="revolute">
		<origin xyz="40 6.2 0.3" rpy="0 0 0" />
        <parent link="world" />
        <child link="center_ball3_link" />
		<axis xyz="0 0 1" />
		<dynamics damping="0.0" friction="0.0"/>
		<limit
		  lower="-4.2745329252"
		  upper="4.235619449"
		  effort="100"
		  velocity="100.236" />
    </joint>
	
	
	<link name="flabellum3_link1">
        <inertial>
            <mass value="1.0" />
            <origin xyz="0 0 0" rpy="0 0 0" />
            <inertia ixx="1" ixy="0" ixz="0" iyy="1" iyz="0" izz="1" />
        </inertial> 
 
        <visual>
            <origin xyz="0 0 0" rpy="0 0 0" />
            <geometry>
                <box size="0.15 0.15 6.0" />
            </geometry>
			<material 
			name="">
			<color
			  rgba="1 0 0 1" />
		  </material>
        </visual>
        
        <collision group="default">
            <origisn xyz="0 0 0" rpy="0 0 0" />
            <geometry>
                 <box size="0.15 0.15 6.0" />
            </geometry>
        </collision>
    </link>
	

    <joint name="flabellum3_joint1" type="fixed">
        <origin xyz="0 0 0" rpy="1.570796327 0 0" />
        <parent link="center_ball3_link" />
        <child link="flabellum3_link1" />
    </joint>
	
	
	<link name="flabellum3_link2">
        <inertial>
            <mass value="1.0" />
            <origin xyz="0 0 0" rpy="0 0 0" />
            <inertia ixx="1" ixy="0" ixz="0" iyy="1" iyz="0" izz="1" />
        </inertial> 
 
        <visual>
            <origin xyz="0 0 0" rpy="0 0 0" />
            <geometry>
                <box size="0.15 0.15 6.0" />
            </geometry>
			<material 
			name="">
			<color
			  rgba="1 0 0 1" />
		  </material>
        </visual>
        
        <collision group="default">
            <origisn xyz="0 0 0" rpy="0 0 0" />
            <geometry>
                 <box size="0.15 0.15 6.0" />
            </geometry>
        </collision>
    </link>
	

    <joint name="flabellum3_joint2" type="fixed">
        <origin xyz="0 0 0" rpy="0 1.570796327 0" />
        <parent link="center_ball3_link" />
        <child link="flabellum3_link2" />
    </joint>


	
	
	
    

	
</robot>
