<?xml version="1.0"?>
<robot name="all in it">
    <link name="world" />
	
	<link name="pendulum_pole_link">
        <inertial>
            <mass value="500.0" />
            <origin xyz="0 0 -2" rpy="0 0 0" />
            <inertia ixx="1" ixy="0" ixz="0" iyy="1" iyz="0" izz="1" />
        </inertial> 
 
        <visual>
            <origin xyz="0 0 -2" rpy="0 0 0" />
            <geometry>
                <box size="0.05 0.05 4" />
            </geometry>
			<material
			name="">
			<color
			  rgba="0.5 0.3 0.9" />
		  </material>
        </visual>
        
        <collision group="default">
            <origisn xyz="0 0 -2" rpy="0 0 0" />
            <geometry>
                 <box size="0.05 0.05 4" />
            </geometry>
        </collision>
    </link>
	
    <joint name="pendulum_pole_joint" type="revolute">
		<origin xyz="27.5 -5 6" rpy="0 0.2 0" />
        <parent link="world" />
        <child link="pendulum_pole_link" />
		<axis xyz="0 1 0" />
		<dynamics damping="0.0" friction="0.0"/>
		<limit
		  lower="1000"
		  upper="1000"
		  effort="1000"
		  velocity="1000" />
    </joint>
	
    <link name="pendulum_ball_link">
        <inertial>
            <mass value="1000" />
            <origin xyz="0 0 0" rpy="0 0 0" />
            <inertia ixx="1.0" ixy="0" ixz="0" iyy="1.0" iyz="0" izz="1.0" />
        </inertial>
        <visual>
            <origin xyz="0 0 0" rpy="0 0 0" />
            <geometry>
                <sphere radius="0.8" />
            </geometry>
			<material 
			name="">
			<color
			  rgba="0 0.3 0.7 1" />
		  </material>
        </visual>
        <collision group="default">
            <origin xyz="0 0 0" rpy="0 0 0" />
            <geometry>
                <sphere radius="0.8" />
            </geometry>
        </collision>
    </link>
    
    <joint name="pendulum_ball_joint" type="fixed">
        <origin xyz="0 0 -4.5" rpy="0 0 0" />
        <parent link="pendulum_pole_link" />
        <child link="pendulum_ball_link" />
    </joint>
    
    
    
    <link name="ground_link">
        <inertial>
            <mass value="1.0" />
            <origin xyz="3.5 0 0" rpy="0 0 0" />
            <inertia ixx="1.0" ixy="0" ixz="0" iyy="1.0" iyz="0" izz="1.0" />
        </inertial>
        <visual>
            <origin xyz="3.5 0 0" rpy="0 0 0" />
            <geometry>
                <box size="7.0 4.0 0.05" />
            </geometry>
        </visual>
        <collision group="default">
            <origin xyz="3.5 0 0" rpy="0 0 0" />
            <geometry>
                <box size="7.0 4.0 0.05" />
            </geometry>
        </collision>
    </link>
    
    <joint name="ground_joint" type="fixed">
        <origin xyz="-1.3 0 -0.15" rpy="0 -0 0" />
        <parent link="world" />
        <child link="ground_link" />
    </joint>
	
	
	
	
    <link name="ground_link1">
        <inertial>
            <mass value="1.0" />
            <origin xyz="0 0 0" rpy="0 0 0" />
            <inertia ixx="1.0" ixy="0" ixz="0" iyy="1.0" iyz="0" izz="1.0" />
        </inertial>
        <visual>
            <origin xyz="0 0 0" rpy="0 0 0" />
            <geometry>
                <box size="10.0 7.0 0.05" />
            </geometry>
        </visual>
        <collision group="default">
            <origin xyz="0 0 0" rpy="0 0 0" />
            <geometry>
                <box size="10.0 7.0 0.05" />
            </geometry>
        </collision>
    </link>
    
    <joint name="ground_joint1" type="fixed">
        <origin xyz="10.5 -3 0" rpy="0 -0 -1.57" />
        <parent link="world" />
        <child link="ground_link1" />
    </joint>
	
	
	<link name="ground_link2">
        <inertial>
            <mass value="1.0" />
            <origin xyz="0 0 0" rpy="0 0 0" />
            <inertia ixx="1.0" ixy="0" ixz="0" iyy="1.0" iyz="0" izz="1.0" />
        </inertial>
        <visual>
            <origin xyz="0 0 0" rpy="0 0 0" />
            <geometry>
                <box size="24.0 8.0 0.05" />
            </geometry>
        </visual>
        <collision group="default">
            <origin xyz="0 0 0" rpy="0 0 0" />
            <geometry>
                <box size="24.0 8.0 0.05" />
            </geometry>
        </collision>
    </link>
    
    <joint name="ground_joint2" type="fixed">
        <origin xyz="19 -13.2 0.15" rpy="0 -0  0" />
        <parent link="world" />
        <child link="ground_link2" />
    </joint>
	
	
    <link name="ground_link3">
        <inertial>
            <mass value="1.0" />
            <origin xyz="9 0 0" rpy="0 0 0" />
            <inertia ixx="1.0" ixy="0" ixz="0" iyy="1.0" iyz="0" izz="1.0" />
        </inertial>
        <visual>
            <origin xyz="9 0 0" rpy="0 0 0" />
            <geometry>
                <box size="18.0 8.0 0.05" />
            </geometry>
        </visual>
        <collision group="default">
            <origin xyz="9 0 0" rpy="0 0 0" />
            <geometry>
                <box size="18.0 8.0 0.05" />
            </geometry>
        </collision>
    </link>
    
    <joint name="ground_joint3" type="fixed">
        <origin xyz="27.8 -8 0.32" rpy="0 -0 1.57" />
        <parent link="world" />
        <child link="ground_link3" />
    </joint>
	
	
	
    <link name="ground_link4">
        <inertial>
            <mass value="1.0" />
            <origin xyz="9 0 0" rpy="0 0 0" />
            <inertia ixx="1.0" ixy="0" ixz="0" iyy="1.0" iyz="0" izz="1.0" />
        </inertial>
        <visual>
            <origin xyz="9 0 0" rpy="0 0 0" />
            <geometry>
                <box size="18.0 8.0 0.05" />
            </geometry>
        </visual>
        <collision group="default">
            <origin xyz="9 0 0" rpy="0 0 0" />
            <geometry>
                <box size="18.0 8.0 0.05" />
            </geometry>
        </collision>
    </link>
    
    <joint name="ground_joint4" type="fixed">
        <origin xyz="33.5 6 0.2" rpy="0 -0 0" />
        <parent link="world" />
        <child link="ground_link4" />
    </joint>
	
	

	
	
    <link name="ball1_link">
        <inertial>
            <mass value="0.1" />
            <origin xyz="0 0 0" rpy="0 0 0" />
            <inertia ixx="1.0" ixy="0" ixz="0" iyy="1.0" iyz="0" izz="1.0" />
        </inertial>
        <visual>
            <origin xyz="0 0 0" rpy="0 0 0" />
            <geometry>
                <sphere radius="0.5" />
            </geometry>
			<material 
			name="">
			<color
			  rgba="1 0 0 0.8" />
		  </material>
        </visual>
        <collision group="default">
            <origin xyz="0 0 0" rpy="0 0 0" />
            <geometry>
                <sphere radius="0.5" />
            </geometry>
        </collision>
    </link>
    
    <joint name="ball1_joint" type="fixed">
        <origin xyz="0 0 5" rpy="0 0 0" />
        <parent link="world" />
        <child link="ball1_link" />
    </joint>
	

    <link name="ball2_link">
        <inertial>
            <mass value="0.1" />
            <origin xyz="0 0 0" rpy="0 0 0" />
            <inertia ixx="1.0" ixy="0" ixz="0" iyy="1.0" iyz="0" izz="1.0" />
        </inertial>
        <visual>
            <origin xyz="0 0 0" rpy="0 0 0" />
            <geometry>
                <sphere radius="0.5" />
            </geometry>
			<material 
			name="">
			<color
			  rgba="0 1 0 0.8" />
		  </material>
        </visual>
        <collision group="default">
            <origin xyz="0 0 0" rpy="0 0 0" />
            <geometry>
                <sphere radius="0.5" />
            </geometry>
        </collision>
    </link>
    
    <joint name="ball2_joint" type="fixed">
        <origin xyz="50.5 6 5" rpy="0 0 0" />
        <parent link="world" />
        <child link="ball2_link" />
    </joint>
	
	
    <link name="box1_link">
        <inertial>
            <mass value="1.0" />
            <origin xyz="0 0 0" rpy="0 0 0" />
            <inertia ixx="1" ixy="0" ixz="0" iyy="1" iyz="0" izz="1" />
        </inertial> 
 
        <visual>
            <origin xyz="0 0 0" rpy="0 0 0" />
            <geometry>
                <box size="0.7 0.7 1" />
            </geometry>
			<material 
			name="">
			<color
			  rgba="0.5 0.3 0 1" />
		  </material>
        </visual>
        
        <collision group="default">
            <origisn xyz="0 0 0" rpy="0 0 0" />
            <geometry>
                 <box size="0.7 0.7 1" />
            </geometry>
        </collision>
    </link>
	

    <joint name="box1_joint_transform" type="floating">
        <origin xyz="1.1 -0.97 0.5" rpy="0 0 -0.2" />
        <parent link="world" />
        <child link="box1_link" />
    </joint>
	
	
    <link name="box2_link">
        <inertial>
            <mass value="1.0" />
            <origin xyz="0 0 0" rpy="0 0 0" />
            <inertia ixx="1" ixy="0" ixz="0" iyy="1" iyz="0" izz="1" />
        </inertial> 
 
        <visual>
            <origin xyz="0 0 0" rpy="0 0 0" />
            <geometry>
                <box size="0.7 0.7 1.2" />
            </geometry>
			<material 
			name="">
			<color
			  rgba="0.7 0 0.6 1" />
		  </material>
        </visual>
        
        <collision group="default">
            <origisn xyz="0 0 0" rpy="0 0 0" />
            <geometry>
                <box size="0.7 0.7 1.2" />
            </geometry>
        </collision>
    </link>
	

    <joint name="box2_joint_transform" type="floating">
        <origin xyz="4 1.5 0.6" rpy="0 0 0.2" />
        <parent link="world" />
        <child link="box2_link" />
    </joint>
	
	
    <link name="box3_link">
        <inertial>
            <mass value="1.0" />
            <origin xyz="0 0 0" rpy="0 0 0" />
            <inertia ixx="1" ixy="0" ixz="0" iyy="1" iyz="0" izz="1" />
        </inertial> 
 
        <visual>
            <origin xyz="0 0 0" rpy="0 0 0" />
            <geometry>
                <box size="0.8 0.3 0.3" />
            </geometry>
			<material 
			name="">
			<color
			  rgba="0 0.4 0.8 1" />
		  </material>
        </visual>
        
        <collision group="default">
            <origisn xyz="0 0 0" rpy="0 0 0" />
            <geometry>
                <box size="0.8 0.3 0.3" />
            </geometry>
        </collision>
    </link>
	

    <joint name="box3_joint_transform" type="floating">
        <origin xyz="9 1.3 0.3" rpy="0 0 0.4" />
        <parent link="world" />
        <child link="box3_link" />
    </joint>
	

    <link name="box4_link">
        <inertial>
            <mass value="1.0" />
            <origin xyz="0 0 0" rpy="0 0 0" />
            <inertia ixx="1" ixy="0" ixz="0" iyy="1" iyz="0" izz="1" />
        </inertial> 
 
        <visual>
            <origin xyz="0 0 0" rpy="0 0 0" />
            <geometry>
                <box size="1.0 0.5 0.4" />
            </geometry>
			<material 
			name="">
			<color
			  rgba="0.9 0.3 0 1" />
		  </material>
        </visual>
        
        <collision group="default">
            <origisn xyz="0 0 0" rpy="0 0 0" />
            <geometry>
                <box size="1.0 0.5 0.4" />
            </geometry>
        </collision>
    </link>
	

    <joint name="box4_joint_transform" type="floating">
        <origin xyz="10.9 -8 0.4" rpy="0 0 -0.4" />
        <parent link="world" />
        <child link="box4_link" />
    </joint>
	
	
    <link name="box5_link">
        <inertial>
            <mass value="1.0" />
            <origin xyz="0 0 0" rpy="0 0 0" />
            <inertia ixx="1" ixy="0" ixz="0" iyy="1" iyz="0" izz="1" />
        </inertial> 
 
        <visual>
            <origin xyz="0 0 0" rpy="0 0 0" />
            <geometry>
                <box size="0.5 0.5 0.5" />
            </geometry>
			<material 
			name="">
			<color
			  rgba="0.5 0.3 0.6 1" />
		  </material>
        </visual>
        
        <collision group="default">
            <origisn xyz="0 0 0" rpy="0 0 0" />
            <geometry>
                <box size="0.5 0.5 0.5" />
            </geometry>
        </collision>
    </link>
	

    <joint name="box5_joint_transform" type="floating">
        <origin xyz="9 -15.5 0.5" rpy="0 0 -0.7" />
        <parent link="world" />
        <child link="box5_link" />
    </joint>

	
	
    <link name="box6_link">
        <inertial>
            <mass value="1.0" />
            <origin xyz="0 0 0" rpy="0 0 0" />
            <inertia ixx="1" ixy="0" ixz="0" iyy="1" iyz="0" izz="1" />
        </inertial> 
 
        <visual>
            <origin xyz="0 0 0" rpy="0 0 0" />
            <geometry>
                <box size="0.5 1 0.5" />
            </geometry>
			<material 
			name="">
			<color
			  rgba="0.5 0.7 0 1" />
		  </material>
        </visual>
        
        <collision group="default">
            <origisn xyz="0 0 0" rpy="0 0 0" />
            <geometry>
                <box size="0.5 1 0.5" />
            </geometry>
        </collision>
    </link>
	

    <joint name="box6_joint_transform" type="floating">
        <origin xyz="24 5 0.7" rpy="0 0 -0.3" />
        <parent link="world" />
        <child link="box6_link" />
    </joint>
	
	
    <link name="box7_link">
        <inertial>
            <mass value="1.0" />
            <origin xyz="0 0 0" rpy="0 0 0" />
            <inertia ixx="1" ixy="0" ixz="0" iyy="1" iyz="0" izz="1" />
        </inertial> 
 
        <visual>
            <origin xyz="0 0 0" rpy="0 0 0" />
            <geometry>
                <box size="0.8 0.8 1.0" />
            </geometry>
			<material 
			name="">
			<color
			  rgba="0.5 0.3 0.2 1" />
		  </material>
        </visual>
        
        <collision group="default">
            <origisn xyz="0 0 0" rpy="0 0 0" />
            <geometry>
                <box size="0.8 0.8 1.0" />
            </geometry>
        </collision>
    </link>
	

    <joint name="box7_joint_transform" type="floating">
        <origin xyz="31 9 0.9" rpy="0 0 0.2" />
        <parent link="world" />
        <child link="box7_link" />
    </joint>
	
	
    <joint name="slope1_link_transform" type="fixed">
        <origin xyz="5.5 0.1 -0.075" rpy="0 0 0" />
        <parent link="world" />
        <child link="slope1_link_transform" />
    </joint>	
	<link name="slope1_link_transform" />
	
    <link name="slope1_link1">
        <inertial>
            <mass value="1.0" />
            <origin xyz="0 0 0" rpy="0 0 0" />
            <inertia ixx="1.0" ixy="0" ixz="0" iyy="1.0" iyz="0" izz="1.0" />
        </inertial>
        <visual>
            <origin xyz="0 0 0" rpy="0 0 0" />
            <geometry>
                <box size="3.0 3.0 0.05" />
            </geometry>
			<material 
			name="">
			<color
			  rgba="0 1 0 1" />
			</material>
        </visual>
        <collision group="default">
            <origin xyz="0 0 0" rpy="0 0 0" />
            <geometry>
                <box size="3.0 3.0 0.05" />
            </geometry>
        </collision>
    </link>
    
    <joint name="slope1_joint1" type="fixed">
        <origin xyz="0 0 0" rpy="0 -0.05 0" />
        <parent link="slope1_link_transform" />
        <child link="slope1_link1" />
    </joint>
	
	
	
	
    <joint name="slope2_link_transform" type="fixed">
        <origin xyz="10.5 -7.7 0.075" rpy="0 0 0" />
        <parent link="world" />
        <child link="slope2_link_transform" />
    </joint>	
	<link name="slope2_link_transform" />
	
    <link name="slope2_link1">
        <inertial>
            <mass value="1.0" />
            <origin xyz="0 0 0" rpy="0 0 0" />
            <inertia ixx="1.0" ixy="0" ixz="0" iyy="1.0" iyz="0" izz="1.0" />
        </inertial>
        <visual>
            <origin xyz="0 0 0" rpy="0 0 0" />
            <geometry>
                <box size="3.0 4.0 0.05" />
            </geometry>
			<material 
			name="">
			<color
			  rgba="0 1 0 1" />
			</material>
        </visual>
        <collision group="default">
            <origin xyz="0 0 0" rpy="0 0 0" />
            <geometry>
                <box size="3.0 4.0 0.05" />
            </geometry>
        </collision>
    </link>
    
    <joint name="slope2_joint1" type="fixed">
        <origin xyz="0 0 0" rpy="0 -0.05 -1.57" />
        <parent link="slope2_link_transform" />
        <child link="slope2_link1" />
    </joint>
	
	
    <joint name="slope3_link_transform" type="fixed">
        <origin xyz="27.5 -9.5 0.235" rpy="0 0 0" />
        <parent link="world" />
        <child link="slope3_link_transform" />
    </joint>	
	<link name="slope3_link_transform" />
	
    <link name="slope3_link1">
        <inertial>
            <mass value="1.0" />
            <origin xyz="0 0 0" rpy="0 0 0" />
            <inertia ixx="1.0" ixy="0" ixz="0" iyy="1.0" iyz="0" izz="1.0" />
        </inertial>
        <visual>
            <origin xyz="0 0 0" rpy="0 0 0" />
            <geometry>
                <box size="3.0 4.0 0.05" />
            </geometry>
			<material 
			name="">
			<color
			  rgba="0 1 0 1" />
			</material>
        </visual>
        <collision group="default">
            <origin xyz="0 0 0" rpy="0 0 0" />
            <geometry>
                <box size="3.0 4.0 0.05" />
            </geometry>
        </collision>
    </link>
    
    <joint name="slope3_joint1" type="fixed">
        <origin xyz="0 0 0" rpy="0 -0.059 1.57" />
        <parent link="slope3_link_transform" />
        <child link="slope3_link1" />
    </joint>
	
	
	
    <joint name="slope4_link_transform" type="fixed">
        <origin xyz="32.80 6 0.26" rpy="0 0 0" />
        <parent link="world" />
        <child link="slope4_link_transform" />
    </joint>	
	<link name="slope4_link_transform" />
	
    <link name="slope4_link1">
        <inertial>
            <mass value="1.0" />
            <origin xyz="0 0 0" rpy="0 0 0" />
            <inertia ixx="1.0" ixy="0" ixz="0" iyy="1.0" iyz="0" izz="1.0" />
        </inertial>
        <visual>
            <origin xyz="0 0 0" rpy="0 0 0" />
            <geometry>
                <box size="2.0 4.0 0.05" />
            </geometry>
			<material 
			name="">
			<color
			  rgba="0 1 0 1" />
			</material>
        </visual>
        <collision group="default">
            <origin xyz="0 0 0" rpy="0 0 0" />
            <geometry>
                <box size="2.0 4.0 0.05" />
            </geometry>
        </collision>
    </link>
    
    <joint name="slope4_joint1" type="fixed">
        <origin xyz="0 0 0" rpy="0 0.065 0" />
        <parent link="slope4_link_transform" />
        <child link="slope4_link1" />
    </joint>
	
	
    <link name="center_ball1_link">
        <inertial>
            <mass value="1.0" />
            <origin xyz="0 0 0" rpy="0 0 0" />
            <inertia ixx="1" ixy="0" ixz="0" iyy="1" iyz="0" izz="1" />
        </inertial> 
 
        <visual>
            <origin xyz="0 0 0" rpy="0 0 0" />
            <geometry>
                <sphere radius="0.1" />
            </geometry>
			<material 
			name="">
			<color
			  rgba="0 0 1 0.5" />
			</material>
        </visual>
        
        <collision group="default">
            <origisn xyz="0 0 0" rpy="0 0 0" />
            <geometry>
                <sphere radius="0.1" />
            </geometry>
        </collision>
    </link>
	

    <joint name="center_ball1_joint" type="revolute">
		<origin xyz="18 -13 0.3" rpy="0 0 0" />
        <parent link="world" />
        <child link="center_ball1_link" />
		<axis xyz="0 0 1" />
		<dynamics damping="0.0" friction="0.0"/>
		<limit
		  lower="-4.2745329252"
		  upper="4.235619449"
		  effort="100"
		  velocity="100.236" />
    </joint>
	
	
	<link name="flabellum1_link1">
        <inertial>
            <mass value="1.0" />
            <origin xyz="0 0 0" rpy="0 0 0" />
            <inertia ixx="1" ixy="0" ixz="0" iyy="1" iyz="0" izz="1" />
        </inertial> 
 
        <visual>
            <origin xyz="0 0 0" rpy="0 0 0" />
            <geometry>
                <box size="0.15 0.15 6.0" />
            </geometry>
			<material 
			name="">
			<color
			  rgba="1 0 0 1" />
		  </material>
        </visual>
        
        <collision group="default">
            <origisn xyz="0 0 0" rpy="0 0 0" />
            <geometry>
                 <box size="0.15 0.15 6.0" />
            </geometry>
        </collision>
    </link>
	

    <joint name="flabellum1_joint1" type="fixed">
        <origin xyz="0 0 0" rpy="1.570796327 0 0" />
        <parent link="center_ball1_link" />
        <child link="flabellum1_link1" />
    </joint>
	
	
	<link name="flabellum1_link2">
        <inertial>
            <mass value="1.0" />
            <origin xyz="0 0 0" rpy="0 0 0" />
            <inertia ixx="1" ixy="0" ixz="0" iyy="1" iyz="0" izz="1" />
        </inertial> 
 
        <visual>
            <origin xyz="0 0 0" rpy="0 0 0" />
            <geometry>
                <box size="0.15 0.15 6.0" />
            </geometry>
			<material 
			name="">
			<color
			  rgba="1 0 0 1" />
		  </material>
        </visual>
        
        <collision group="default">
            <origisn xyz="0 0 0" rpy="0 0 0" />
            <geometry>
                 <box size="0.15 0.15 6.0" />
            </geometry>
        </collision>
    </link>
	

    <joint name="flabellum1_joint2" type="fixed">
        <origin xyz="0 0 0" rpy="0 1.570796327 0" />
        <parent link="center_ball1_link" />
        <child link="flabellum1_link2" />
    </joint>
	


    <link name="center_ball2_link">
        <inertial>
            <mass value="1.0" />
            <origin xyz="0 0 0" rpy="0 0 0" />
            <inertia ixx="1" ixy="0" ixz="0" iyy="1" iyz="0" izz="1" />
        </inertial> 
 
        <visual>
            <origin xyz="0 0 0" rpy="0 0 0" />
            <geometry>
                <sphere radius="0.1" />
            </geometry>
			<material 
			name="">
			<color
			  rgba="0 0 1 0.5" />
		  </material>
        </visual>
        
        <collision group="default">
            <origisn xyz="0 0 0" rpy="0 0 0" />
            <geometry>
                <sphere radius="0.1" />
            </geometry>
        </collision>
    </link>
	

    <joint name="center_ball2_joint" type="revolute">
		<origin xyz="27.2 0.2 0.45" rpy="0 0 0" />
        <parent link="world" />
        <child link="center_ball2_link" />
		<axis xyz="0 0 1" />
		<dynamics damping="0.0" friction="0.0"/>
		<limit
		  lower="-4.2745329252"
		  upper="4.235619449"
		  effort="100"
		  velocity="100.236" />
    </joint>
	
	
	<link name="flabellum2_link1">
        <inertial>
            <mass value="1.0" />
            <origin xyz="0 0 0" rpy="0 0 0" />
            <inertia ixx="1" ixy="0" ixz="0" iyy="1" iyz="0" izz="1" />
        </inertial> 
 
        <visual>
            <origin xyz="0 0 0" rpy="0 0 0" />
            <geometry>
                <box size="0.15 0.15 6.0" />
            </geometry>
			<material 
			name="">
			<color
			  rgba="1 0 0 1" />
		  </material>
        </visual>
        
        <collision group="default">
            <origisn xyz="0 0 0" rpy="0 0 0" />
            <geometry>
                 <box size="0.15 0.15 6.0" />
            </geometry>
        </collision>
    </link>
	

    <joint name="flabellum2_joint1" type="fixed">
        <origin xyz="0 0 0" rpy="1.570796327 0 0" />
        <parent link="center_ball2_link" />
        <child link="flabellum2_link1" />
    </joint>
	
	
	<link name="flabellum2_link2">
        <inertial>
            <mass value="1.0" />
            <origin xyz="0 0 0" rpy="0 0 0" />
            <inertia ixx="1" ixy="0" ixz="0" iyy="1" iyz="0" izz="1" />
        </inertial> 
 
        <visual>
            <origin xyz="0 0 0" rpy="0 0 0" />
            <geometry>
                <box size="0.15 0.15 6.0" />
            </geometry>
			<material 
			name="">
			<color
			  rgba="1 0 0 1" />
		  </material>
        </visual>
        
        <collision group="default">
            <origisn xyz="0 0 0" rpy="0 0 0" />
            <geometry>
                 <box size="0.15 0.15 6.0" />
            </geometry>
        </collision>
    </link>
	

    <joint name="flabellum2_joint2" type="fixed">
        <origin xyz="0 0 0" rpy="0 1.570796327 0" />
        <parent link="center_ball2_link" />
        <child link="flabellum2_link2" />
    </joint>
	
	
	
    <link name="center_ball3_link">
        <inertial>
            <mass value="1.0" />
            <origin xyz="0 0 0" rpy="0 0 0" />
            <inertia ixx="1" ixy="0" ixz="0" iyy="1" iyz="0" izz="1" />
        </inertial> 
 
        <visual>
            <origin xyz="0 0 0" rpy="0 0 0" />
            <geometry>
                <sphere radius="0.1" />
            </geometry>
			<material 
			name="">
			<color
			  rgba="0 0 1 0.5" />
		  </material>
        </visual>
        
        <collision group="default">
            <origisn xyz="0 0 0" rpy="0 0 0" />
            <geometry>
                <sphere radius="0.1" />
            </geometry>
        </collision>
    </link>
	

    <joint name="center_ball3_joint" type="revolute">
		<origin xyz="40 6.2 0.3" rpy="0 0 0" />
        <parent link="world" />
        <child link="center_ball3_link" />
		<axis xyz="0 0 1" />
		<dynamics damping="0.0" friction="0.0"/>
		<limit
		  lower="-4.2745329252"
		  upper="4.235619449"
		  effort="100"
		  velocity="100.236" />
    </joint>
	
	
	<link name="flabellum3_link1">
        <inertial>
            <mass value="1.0" />
            <origin xyz="0 0 0" rpy="0 0 0" />
            <inertia ixx="1" ixy="0" ixz="0" iyy="1" iyz="0" izz="1" />
        </inertial> 
 
        <visual>
            <origin xyz="0 0 0" rpy="0 0 0" />
            <geometry>
                <box size="0.15 0.15 6.0" />
            </geometry>
			<material 
			name="">
			<color
			  rgba="1 0 0 1" />
		  </material>
        </visual>
        
        <collision group="default">
            <origisn xyz="0 0 0" rpy="0 0 0" />
            <geometry>
                 <box size="0.15 0.15 6.0" />
            </geometry>
        </collision>
    </link>
	

    <joint name="flabellum3_joint1" type="fixed">
        <origin xyz="0 0 0" rpy="1.570796327 0 0" />
        <parent link="center_ball3_link" />
        <child link="flabellum3_link1" />
    </joint>
	
	
	<link name="flabellum3_link2">
        <inertial>
            <mass value="1.0" />
            <origin xyz="0 0 0" rpy="0 0 0" />
            <inertia ixx="1" ixy="0" ixz="0" iyy="1" iyz="0" izz="1" />
        </inertial> 
 
        <visual>
            <origin xyz="0 0 0" rpy="0 0 0" />
            <geometry>
                <box size="0.15 0.15 6.0" />
            </geometry>
			<material 
			name="">
			<color
			  rgba="1 0 0 1" />
		  </material>
        </visual>
        
        <collision group="default">
            <origisn xyz="0 0 0" rpy="0 0 0" />
            <geometry>
                 <box size="0.15 0.15 6.0" />
            </geometry>
        </collision>
    </link>
	

    <joint name="flabellum3_joint2" type="fixed">
        <origin xyz="0 0 0" rpy="0 1.570796327 0" />
        <parent link="center_ball3_link" />
        <child link="flabellum3_link2" />
    </joint>
    
    
	<link name="base_link">
		<inertial>
            <mass value="10.0" />
            <origin xyz="0 0 0" rpy="0 0 0" />
            <inertia ixx="1" ixy="0" ixz="0" iyy="1" iyz="0" izz="1" />
        </inertial> 
 
        <visual>
            <origin xyz="0 0 0" rpy="0 0 0" />
            <geometry>
                <box size="0.2 0.2 0.2" />
            </geometry>
			<material 
			name="">
			<color
			  rgba="0.5 0.9 0.2 1" />
		  </material>
        </visual>
        
        <collision group="default">
            <origisn xyz="0 0 0" rpy="0 0 0" />
            <geometry>
                <box size="0.2 0.2 0.2" />
            </geometry>
        </collision>
    </link>
	<joint name="base_joint" type="floating">
        <origin xyz="9.5 -3 0.13" rpy="0 0 0" />
        <parent link="world" />
        <child link="base_link" />
    </joint>
    
    
	<link name="board_link">
        <inertial>
            <mass value="10.0" />
            <origin xyz="0 0 0" rpy="0 0 0" />
            <inertia ixx="1" ixy="0" ixz="0" iyy="1" iyz="0" izz="1" />
        </inertial> 
 
        <visual>
            <origin xyz="0 0 0" rpy="0 0 0" />
            <geometry>
                <box size="3.0 3.0 0.01" />
            </geometry>
			<material 
			name="">
			<color
			  rgba="0.7 0.9 0.7 1" />
		  </material>
        </visual>
        
        <collision group="default">
            <origisn xyz="0 0. 0" rpy="0 0 0" />
            <geometry>
                <box size="3.0 3.0 0.01" />
            </geometry>
        </collision>
    </link>
	

    <joint name="board_joint" type="floating">
        <origin xyz="9.5 -2.5 0.33" rpy="0 0 0.3" />
        <parent link="world" />
        <child link="board_link" />
    </joint>
    
    
    
    

    
    



	
</robot>

