<?xml version="1.0"?>
<robot name="all in it">
    <link name="world" />
	
    <link name="ground_link">
        <inertial>
            <mass value="1.0" />
            <origin xyz="4 0 0" rpy="0 0 0" />
            <inertia ixx="1.0" ixy="0" ixz="0" iyy="1.0" iyz="0" izz="1.0" />
        </inertial>
        <visual>
            <origin xyz="4 0 0" rpy="0 0 0" />
            <geometry>
                <box size="8.0 4.0 0.05" />
            </geometry>
        </visual>
        <collision group="default">
            <origin xyz="4 0 0" rpy="0 0 0" />
            <geometry>
                <box size="8.0 4.0 0.05" />
            </geometry>
        </collision>
    </link>
    
    <joint name="ground_joint" type="fixed">
        <origin xyz="-1 0 0" rpy="0 -0 0.3" />
        <parent link="world" />
        <child link="ground_link" />
    </joint>
	
	
	
	
    <link name="ground_link1">
        <inertial>
            <mass value="1.0" />
            <origin xyz="4 0 0" rpy="0 0 0" />
            <inertia ixx="1.0" ixy="0" ixz="0" iyy="1.0" iyz="0" izz="1.0" />
        </inertial>
        <visual>
            <origin xyz="4 0 0" rpy="0 0 0" />
            <geometry>
                <box size="8.0 4.0 0.05" />
            </geometry>
        </visual>
        <collision group="default">
            <origin xyz="4 0 0" rpy="0 0 0" />
            <geometry>
                <box size="8.0 4.0 0.05" />
            </geometry>
        </collision>
    </link>
    
    <joint name="ground_joint1" type="fixed">
        <origin xyz="7 2 0" rpy="0 -0 -0.4" />
        <parent link="world" />
        <child link="ground_link1" />
    </joint>
	
	
	
	
	
	<link name="ground_link2">
        <inertial>
            <mass value="1.0" />
            <origin xyz="4 0 0" rpy="0 0 0" />
            <inertia ixx="1.0" ixy="0" ixz="0" iyy="1.0" iyz="0" izz="1.0" />
        </inertial>
        <visual>
            <origin xyz="4 0 0" rpy="0 0 0" />
            <geometry>
                <box size="8.0 4.0 0.05" />
            </geometry>
        </visual>
        <collision group="default">
            <origin xyz="4 0 0" rpy="0 0 0" />
            <geometry>
                <box size="8.0 4.0 0.05" />
            </geometry>
        </collision>
    </link>
    
    <joint name="ground_joint2" type="fixed">
        <origin xyz="14 -1.5 0" rpy="0 -0 -0.2" />
        <parent link="world" />
        <child link="ground_link2" />
    </joint>
	
	
	
	
	
	<link name="ground_link3">
        <inertial>
            <mass value="1.0" />
            <origin xyz="9 0 0" rpy="0 0 0" />
            <inertia ixx="1.0" ixy="0" ixz="0" iyy="1.0" iyz="0" izz="1.0" />
        </inertial>
        <visual>
            <origin xyz="9 0 0" rpy="0 0 0" />
            <geometry>
                <box size="18.0 4.0 0.05" />
            </geometry>
        </visual>
        <collision group="default">
            <origin xyz="9 0 0" rpy="0 0 0" />
            <geometry>
                <box size="18.0 4.0 0.05" />
            </geometry>
        </collision>
    </link>
    
    <joint name="ground_joint3" type="fixed">
        <origin xyz="21.1 -5 0" rpy="0 -0 0.25" />
        <parent link="world" />
        <child link="ground_link3" />
    </joint>
	
	
	
	<link name="ball1_link">
        <inertial>
            <mass value="0.1" />
            <origin xyz="0 0 0" rpy="0 0 0" />
            <inertia ixx="1.0" ixy="0" ixz="0" iyy="1.0" iyz="0" izz="1.0" />
        </inertial>
        <visual>
            <origin xyz="0 0 0" rpy="0 0 0" />
            <geometry>
                <sphere radius="0.5" />
            </geometry>
			<material 
			name="">
			<color
			  rgba="1 0 0 0.8" />
		  </material>
        </visual>
        <collision group="default">
            <origin xyz="0 0 0" rpy="0 0 0" />
            <geometry>
                <sphere radius="0.5" />
            </geometry>
        </collision>
    </link>
    
    <joint name="ball1_joint" type="fixed">
        <origin xyz="0 0 5" rpy="0 0 0" />
        <parent link="world" />
        <child link="ball1_link" />
    </joint>
	

	<link name="ball2_link">
        <inertial>
            <mass value="0.1" />
            <origin xyz="0 0 0" rpy="0 0 0" />
            <inertia ixx="1.0" ixy="0" ixz="0" iyy="1.0" iyz="0" izz="1.0" />
        </inertial>
        <visual>
            <origin xyz="0 0 0" rpy="0 0 0" />
            <geometry>
                <sphere radius="0.5" />
            </geometry>
			<material 
			name="">
			<color
			  rgba="0 1 0 0.8" />
		  </material>
        </visual>
        <collision group="default">
            <origin xyz="0 0 0" rpy="0 0 0" />
            <geometry>
                <sphere radius="0.5" />
            </geometry>
        </collision>
    </link>
    
    <joint name="ball2_joint" type="fixed">
        <origin xyz="36 0.38 5" rpy="0 0 0" />
        <parent link="world" />
        <child link="ball2_link" />
    </joint>
	
	
	<link name="box_link1">
        <inertial>
            <mass value="1.0" />
            <origin xyz="0 0 0" rpy="0 0 0" />
            <inertia ixx="1" ixy="0" ixz="0" iyy="1" iyz="0" izz="1" />
        </inertial> 
 
        <visual>
            <origin xyz="0 0 0" rpy="0 0 0" />
            <geometry>
                <box size="0.7 0.7 1" />
            </geometry>
			<material 
			name="">
			<color
			  rgba="0.5 0.3 0 1" />
		  </material>
        </visual>
        
        <collision group="default">
            <origisn xyz="0 0 0" rpy="0 0 0" />
            <geometry>
                 <box size="0.7 0.7 1" />
            </geometry>
        </collision>
    </link>
	

    <joint name="box_joint_transform1" type="floating">
        <origin xyz="0.88 -0.6 0.5" rpy="0 0 -0.2" />
        <parent link="world" />
        <child link="box_link1" />
    </joint>
	
	
	<link name="box_link2">
        <inertial>
            <mass value="1.0" />
            <origin xyz="0 0 0" rpy="0 0 0" />
            <inertia ixx="1" ixy="0" ixz="0" iyy="1" iyz="0" izz="1" />
        </inertial> 
 
        <visual>
            <origin xyz="0 0 0" rpy="0 0 0" />
            <geometry>
                <box size="0.7 0.7 1.2" />
            </geometry>
			<material 
			name="">
			<color
			  rgba="0.7 0 0.6 1" />
		  </material>
        </visual>
        
        <collision group="default">
            <origisn xyz="0 0 0" rpy="0 0 0" />
            <geometry>
                <box size="0.7 0.7 1.2" />
            </geometry>
        </collision>
    </link>
	

    <joint name="box_joint_transform2" type="floating">
        <origin xyz="4 1.5 0.6" rpy="0 0 0.2" />
        <parent link="world" />
        <child link="box_link2" />
    </joint>

	<link name="box_link3">
        <inertial>
            <mass value="1.0" />
            <origin xyz="0 0 0" rpy="0 0 0" />
            <inertia ixx="1" ixy="0" ixz="0" iyy="1" iyz="0" izz="1" />
        </inertial> 
 
        <visual>
            <origin xyz="0 0 0" rpy="0 0 0" />
            <geometry>
                <box size="0.8 0.3 0.3" />
            </geometry>
			<material 
			name="">
			<color
			  rgba="0 0.4 0.8 1" />
		  </material>
        </visual>
        
        <collision group="default">
            <origisn xyz="0 0 0" rpy="0 0 0" />
            <geometry>
                <box size="0.8 0.3 0.3" />
            </geometry>
        </collision>
    </link>
	

    <joint name="box_joint_transform3" type="floating">
        <origin xyz="8 1.9 0.3" rpy="0 0 0.4" />
        <parent link="world" />
        <child link="box_link3" />
    </joint>
	
	
	<link name="box_link4">
        <inertial>
            <mass value="1.0" />
            <origin xyz="0 0 0" rpy="0 0 0" />
            <inertia ixx="1" ixy="0" ixz="0" iyy="1" iyz="0" izz="1" />
        </inertial> 
 
        <visual>
            <origin xyz="0 0 0" rpy="0 0 0" />
            <geometry>
                <box size="1.0 0.5 0.4" />
            </geometry>
			<material 
			name="">
			<color
			  rgba="0.9 0.3 0 1" />
		  </material>
        </visual>
        
        <collision group="default">
            <origisn xyz="0 0 0" rpy="0 0 0" />
            <geometry>
                <box size="1.0 0.5 0.4" />
            </geometry>
        </collision>
    </link>
	

    <joint name="box_joint_transform4" type="floating">
        <origin xyz="10 -1 0.3" rpy="0 0 0" />
        <parent link="world" />
        <child link="box_link4" />
    </joint>
	
	
	
	<link name="box_link5">
        <inertial>
            <mass value="1.0" />
            <origin xyz="0 0 0" rpy="0 0 0" />
            <inertia ixx="1" ixy="0" ixz="0" iyy="1" iyz="0" izz="1" />
        </inertial> 
 
        <visual>
            <origin xyz="0 0 0" rpy="0 0 0" />
            <geometry>
                <box size="0.5 0.5 0.5" />
            </geometry>
			<material 
			name="">
			<color
			  rgba="0.5 0.3 0.6 1" />
		  </material>
        </visual>
        
        <collision group="default">
            <origisn xyz="0 0 0" rpy="0 0 0" />
            <geometry>
                <box size="0.5 0.5 0.5" />
            </geometry>
        </collision>
    </link>
	

    <joint name="box_joint_transform5" type="floating">
        <origin xyz="12 -2 0.3" rpy="0 0 -0.1" />
        <parent link="world" />
        <child link="box_link5" />
    </joint>
	
    <link name="box_link6">
        <inertial>
            <mass value="1.0" />
            <origin xyz="0 0 0" rpy="0 0 0" />
            <inertia ixx="1" ixy="0" ixz="0" iyy="1" iyz="0" izz="1" />
        </inertial> 
 
        <visual>
            <origin xyz="0 0 0" rpy="0 0 0" />
            <geometry>
                <box size="0.5 1 0.5" />
            </geometry>
			<material 
			name="">
			<color
			  rgba="0.5 0.7 0 1" />
		  </material>
        </visual>
        
        <collision group="default">
            <origisn xyz="0 0 0" rpy="0 0 0" />
            <geometry>
                <box size="0.5 1 0.5" />
            </geometry>
        </collision>
    </link>
	

    <joint name="box_joint_transform6" type="floating">
        <origin xyz="15 0 0.3" rpy="0 0 -0.3" />
        <parent link="world" />
        <child link="box_link6" />
    </joint>
	
	
	<link name="box_link7">
        <inertial>
            <mass value="1.0" />
            <origin xyz="0 0 0" rpy="0 0 0" />
            <inertia ixx="1" ixy="0" ixz="0" iyy="1" iyz="0" izz="1" />
        </inertial> 
 
        <visual>
            <origin xyz="0 0 0" rpy="0 0 0" />
            <geometry>
                <box size="0.8 0.8 1.0" />
            </geometry>
			<material 
			name="">
			<color
			  rgba="0.5 0.3 0.2 1" />
		  </material>
        </visual>
        
        <collision group="default">
            <origisn xyz="0 0 0" rpy="0 0 0" />
            <geometry>
                <box size="0.8 0.8 1.0" />
            </geometry>
        </collision>
    </link>
	

    <joint name="box_joint_transform7" type="floating">
        <origin xyz="19 -1 0.5" rpy="0 0 0.2" />
        <parent link="world" />
        <child link="box_link7" />
    </joint>
	
	
	
	<link name="box_link8">
        <inertial>
            <mass value="1.0" />
            <origin xyz="0 0 0" rpy="0 0 0" />
            <inertia ixx="1" ixy="0" ixz="0" iyy="1" iyz="0" izz="1" />
        </inertial> 
 
        <visual>
            <origin xyz="0 0 0" rpy="0 0 0" />
            <geometry>
                <box size="0.5 0.5 0.5" />
            </geometry>
			<material 
			name="">
			<color
			  rgba="0.5 0.8 0.6 1" />
		  </material>
        </visual>
        
        <collision group="default">
            <origisn xyz="0 0 0" rpy="0 0 0" />
            <geometry>
                <box size="0.5 0.5 0.5" />
            </geometry>
        </collision>
    </link>
	

    <joint name="box_joint_transform8" type="floating">
        <origin xyz="23 -2.6 0.3" rpy="0 0 0.1" />
        <parent link="world" />
        <child link="box_link8" />
    </joint>
	
	
	<link name="box_link9">
        <inertial>
            <mass value="1.0" />
            <origin xyz="0 0 0" rpy="0 0 0" />
            <inertia ixx="1" ixy="0" ixz="0" iyy="1" iyz="0" izz="1" />
        </inertial> 
 
        <visual>
            <origin xyz="0 0 0" rpy="0 0 0" />
            <geometry>
                <sphere radius="0.2" />
            </geometry>
			<material 
			name="">
			<color
			  rgba="0.9 0.1 0 1" />
		  </material>
        </visual>
        
        <collision group="default">
            <origisn xyz="0 0 0" rpy="0 0 0" />
            <geometry>
                <sphere radius="0.2" />
            </geometry>
        </collision>
    </link>
	

    <joint name="box_joint_transform9" type="floating">
        <origin xyz="26 -3.2 0.3" rpy="0 0 0.2" />
        <parent link="world" />
        <child link="box_link9" />
    </joint>
	
	
	
	<link name="box_link10">
        <inertial>
            <mass value="1.0" />
            <origin xyz="0 0 0" rpy="0 0 0" />
            <inertia ixx="1" ixy="0" ixz="0" iyy="1" iyz="0" izz="1" />
        </inertial> 
 
        <visual>
            <origin xyz="0 0 0" rpy="0 0 0" />
            <geometry>
                <box size="0.5 0.5 0.5" />
            </geometry>
			<material 
			name="">
			<color
			  rgba="0.2 0.3 0 1" />
		  </material>
        </visual>
        
        <collision group="default">
            <origisn xyz="0 0 0" rpy="0 0 0" />
            <geometry>
                <box size="0.5 0.5 0.5" />
            </geometry>
        </collision>
    </link>
	

    <joint name="box_joint_transform10" type="floating">
        <origin xyz="30 -1 0.3" rpy="0 0 -0.2" />
        <parent link="world" />
        <child link="box_link10" />
    </joint>
	
	
	
	
	
</robot>

